<?xml version="1.0"?>
<robot xmlns:xacro="http://ros.org/xacro" name="rbot">

<xacro:arg name="type" default="rbot"/>


  <!--COLOURS FOR THE THE LINKS-->

  <material name="blue">
    <color rgba="0 0 0.8 1"/>
  </material>
  <material name="black">
    <color rgba="0 0 0 1"/>
  </material>
  <material name="green">
    <color rgba="0.2 1 0.2 1"/>
  </material>
    <material name="red">
    <color rgba="1 0 0 1"/>
  </material>


  <!-- BASE LINK -->
  
  <link name="base_link">
    <visual>
        <origin xyz="0.15 0 0.075"/>
        <geometry>
            <box size="0.3 0.3 0.15"/>
        </geometry>
        <material name="blue"/>
    </visual>
    <collision>
        <origin xyz="0.15 0 0.075"/>
        <geometry>
            <box size="0.3 0.3 0.15"/>
        </geometry>
    </collision>

  </link>


  <!-- RIGHT WHEEL-->
 
  <link name="right_wheel">
    <visual>
      <geometry>
        <cylinder length="0.04" radius="0.05"/>
      </geometry>
 	    <material name="green"/>
    </visual>
    <collision>
      <geometry>
        <cylinder length="0.04" radius="0.05"/>
      </geometry>
    </collision>

  </link>



  <!--RIGHT WHEEL JOINT-->

  <joint name="right_wheel_joint" type="continuous">
    <parent link="base_link"/>
    <child link="right_wheel"/>
    <origin rpy="1.57075 0 0" xyz="0 -0.175 0"/>
    <axis xyz="0 0 -1"/>
  </joint>
 
  <!--LEFT WHEEL-->

  <link name="left_wheel">
    <visual>
      <geometry>
        <cylinder length="0.04" radius="0.05"/>
      </geometry>
 	    <material name="green"/>
    </visual>
    <collision>
      <geometry>
        <cylinder length="0.04" radius="0.05"/>
      </geometry>
    </collision>




  <!--LEFT WHEEL JOINT-->

  <joint name="left_wheel_joint" type="continuous">
    <parent link="base_link"/>
    <child link="left_wheel"/>
    <origin rpy="-1.57075 0 0" xyz="0 0.175 0"/>
    <axis xyz="0 0 1"/>
  </joint>

  <!--CASTER WHEEL-->

  <link name="caster_wheel">
    <visual>
      <geometry>
        <sphere radius="0.05"/>
      </geometry>
  	<material name="black"/>
    </visual>
    <collision>
      <geometry>
        <sphere radius="0.05"/>
      </geometry>
    </collision>

  </link>
  

  <!--CASTER WHEEL JOINT-->

  <joint name="caster_wheel_joint" type="fixed">
    <parent link="base_link"/>
    <child link="caster_wheel"/>
    <origin xyz="0.24 0 0"/>
  </joint>
</robot>
